<?xml version="1.0" ?>
<robot name="evpi"
  xmlns:xacro="http://ros.org/wiki/xacro">


  <!-- ****************** ROBOT BASE FOOTPRINT ***************************  -->
  <link name="base_footprint"/>
  
  <joint name="base_joint" type="fixed">
    <parent link="base_footprint"/>
    <child link="base_link"/>
    <origin xyz="0 0 0.2" rpy="0 0 0"/>
  </joint>

  <!-- ********************** ROBOT BASE *********************************  -->
  <link name="base_link"/>
	
  <joint name="fork_joint" type="revolute">
    <parent link="base_link"/>
    <child link="fork_link"/>
    <origin xyz="0.63 0 0.05" rpy="0 0 0"/>
    <axis xyz="0 0 1"/>
    <limit effort="1000.0" lower="-0.7" upper="0.7" velocity="0.5"/>
  </joint>
  
  <link name="fork_link"/>

  <!-- *********************** REAR WHEELS ******************************  -->
  <joint name="wheel_rear_joint" type="continuous">
    <parent link="base_link"/>
    <child link="wheel_rear_link"/>
    <origin xyz="-0.5 0.0 0.15" rpy="0 0 -1.57"/>
    <axis xyz="1 0 0"/>
  </joint>

  <link name="wheel_rear_link"/>

  <!-- *********************** FRONT WHEELS ******************************  -->
  <joint name="wheel_left_joint" type="fixed">
    <parent link="fork_link"/>
    <child link="wheel_left_link"/>
    <origin xyz="0.63 -0.45 0.02" rpy="0 0 -1.57"/>
    <axis xyz="1 0 0"/>
  </joint>

  <link name="wheel_left_link"/>

  <joint name="wheel_right_joint" type="fixed">
    <parent link="fork_link"/>
    <child link="wheel_right_link"/>
    <origin xyz="0.63 0.45 0.02" rpy="0 0 -1.57"/>
    <axis xyz="1 0 0"/>
  </joint>

  <link name="wheel_right_link"/>

  <!-- *********************** IMU SETUP *********************************  -->
 
  <joint name="imu_joint" type="fixed">
    <parent link="base_link"/>
    <child link="imu_link"/>
    <origin xyz="0.64 0 0.64" rpy="0 0 0"/>
  </joint>

  <link name="imu_link"/>

  <!-- *********************** Camera SETUP *********************************  -->
 
  <joint name="camera_joint" type="fixed">
    <parent link="base_link"/>
    <child link="camera_link"/>
    <origin xyz="0.75 0 0.665" rpy="0 0 0"/>
  </joint>

  <link name="camera_link"/>

  <!-- *********************** Lidar SETUP *********************************  -->
 
  <joint name="velodyne_top_joint" type="fixed">
    <parent link="base_link"/>
    <child link="velodyne_top_link"/>
    <origin xyz="-0.69 0 1.8" rpy="0 0 0"/>
  </joint>

  <link name="velodyne_top_link"/>
 
  <joint name="velodyne_front_joint" type="fixed">
    <parent link="base_link"/>
    <child link="velodyne_front_link"/>
    <origin xyz="0.55 0.0 0.86" rpy="3.14 0 0"/>
  </joint>

  <link name="velodyne_front_link"/>

</robot>
